Watching for file changes with StatReloader
D:\JOB\freelance10\converter\payment\modulbank_pay.py changed, reloading.
Watching for file changes with StatReloader
Watching for file changes with StatReloader
Not Found: /ad
Internal Server Error: /ru/payment/catch-payment/
Traceback (most recent call last):
  File "D:\python38\lib\site-packages\django\db\models\fields\__init__.py", line 2053, in get_prep_value
    return int(value)
ValueError: invalid literal for int() with base 10: '2hbpw7ncf4'

The above exception was the direct cause of the following exception:

Traceback (most recent call last):
  File "D:\python38\lib\site-packages\django\core\handlers\exception.py", line 55, in inner
    response = get_response(request)
  File "D:\python38\lib\site-packages\django\core\handlers\base.py", line 197, in _get_response
    response = wrapped_callback(request, *callback_args, **callback_kwargs)
  File "D:\python38\lib\site-packages\django\views\decorators\csrf.py", line 56, in wrapper_view
    return view_func(*args, **kwargs)
  File "D:\JOB\freelance10\converter\users\decorators.py", line 46, in wrapper
    return func(request, *args, **kwargs)
  File "D:\JOB\freelance10\converter\payment\views.py", line 46, in catch_payment
    order.save()
  File "D:\JOB\freelance10\converter\convert_order\models.py", line 36, in save
    super(ConvertOrder, self).save(*args, **kwargs) ### ÏÅÐÅÃÐÓÆÀÅÒ ÑÈÑÒÅÌÓ !!!!
  File "D:\python38\lib\site-packages\django\db\models\base.py", line 814, in save
    self.save_base(
  File "D:\python38\lib\site-packages\django\db\models\base.py", line 877, in save_base
    updated = self._save_table(
  File "D:\python38\lib\site-packages\django\db\models\base.py", line 990, in _save_table
    updated = self._do_update(
  File "D:\python38\lib\site-packages\django\db\models\base.py", line 1054, in _do_update
    return filtered._update(values) > 0
  File "D:\python38\lib\site-packages\django\db\models\query.py", line 1231, in _update
    return query.get_compiler(self.db).execute_sql(CURSOR)
  File "D:\python38\lib\site-packages\django\db\models\sql\compiler.py", line 1984, in execute_sql
    cursor = super().execute_sql(result_type)
  File "D:\python38\lib\site-packages\django\db\models\sql\compiler.py", line 1549, in execute_sql
    sql, params = self.as_sql()
  File "D:\python38\lib\site-packages\django\db\models\sql\compiler.py", line 1947, in as_sql
    val = field.get_db_prep_save(val, connection=self.connection)
  File "D:\python38\lib\site-packages\django\db\models\fields\__init__.py", line 954, in get_db_prep_save
    return self.get_db_prep_value(value, connection=connection, prepared=False)
  File "D:\python38\lib\site-packages\django\db\models\fields\__init__.py", line 2060, in get_db_prep_value
    value = super().get_db_prep_value(value, connection, prepared)
  File "D:\python38\lib\site-packages\django\db\models\fields\__init__.py", line 947, in get_db_prep_value
    value = self.get_prep_value(value)
  File "D:\python38\lib\site-packages\django\db\models\fields\__init__.py", line 2055, in get_prep_value
    raise e.__class__(
ValueError: Field 'price' expected a number but got '2hbpw7ncf4'.
Internal Server Error: /ru/payment/catch-payment/
Traceback (most recent call last):
  File "D:\python38\lib\site-packages\django\db\models\fields\__init__.py", line 2053, in get_prep_value
    return int(value)
ValueError: invalid literal for int() with base 10: '2hbpw7ncf4'

The above exception was the direct cause of the following exception:

Traceback (most recent call last):
  File "D:\python38\lib\site-packages\django\core\handlers\exception.py", line 55, in inner
    response = get_response(request)
  File "D:\python38\lib\site-packages\django\core\handlers\base.py", line 197, in _get_response
    response = wrapped_callback(request, *callback_args, **callback_kwargs)
  File "D:\python38\lib\site-packages\django\views\decorators\csrf.py", line 56, in wrapper_view
    return view_func(*args, **kwargs)
  File "D:\JOB\freelance10\converter\users\decorators.py", line 46, in wrapper
    return func(request, *args, **kwargs)
  File "D:\JOB\freelance10\converter\payment\views.py", line 46, in catch_payment
    order.save()
  File "D:\JOB\freelance10\converter\convert_order\models.py", line 36, in save
    super(ConvertOrder, self).save(*args, **kwargs) ### ÏÅÐÅÃÐÓÆÀÅÒ ÑÈÑÒÅÌÓ !!!!
  File "D:\python38\lib\site-packages\django\db\models\base.py", line 814, in save
    self.save_base(
  File "D:\python38\lib\site-packages\django\db\models\base.py", line 877, in save_base
    updated = self._save_table(
  File "D:\python38\lib\site-packages\django\db\models\base.py", line 990, in _save_table
    updated = self._do_update(
  File "D:\python38\lib\site-packages\django\db\models\base.py", line 1054, in _do_update
    return filtered._update(values) > 0
  File "D:\python38\lib\site-packages\django\db\models\query.py", line 1231, in _update
    return query.get_compiler(self.db).execute_sql(CURSOR)
  File "D:\python38\lib\site-packages\django\db\models\sql\compiler.py", line 1984, in execute_sql
    cursor = super().execute_sql(result_type)
  File "D:\python38\lib\site-packages\django\db\models\sql\compiler.py", line 1549, in execute_sql
    sql, params = self.as_sql()
  File "D:\python38\lib\site-packages\django\db\models\sql\compiler.py", line 1947, in as_sql
    val = field.get_db_prep_save(val, connection=self.connection)
  File "D:\python38\lib\site-packages\django\db\models\fields\__init__.py", line 954, in get_db_prep_save
    return self.get_db_prep_value(value, connection=connection, prepared=False)
  File "D:\python38\lib\site-packages\django\db\models\fields\__init__.py", line 2060, in get_db_prep_value
    value = super().get_db_prep_value(value, connection, prepared)
  File "D:\python38\lib\site-packages\django\db\models\fields\__init__.py", line 947, in get_db_prep_value
    value = self.get_prep_value(value)
  File "D:\python38\lib\site-packages\django\db\models\fields\__init__.py", line 2055, in get_prep_value
    raise e.__class__(
ValueError: Field 'price' expected a number but got '2hbpw7ncf4'.
Internal Server Error: /ru/payment/catch-payment/
Traceback (most recent call last):
  File "D:\python38\lib\site-packages\django\db\models\fields\__init__.py", line 2053, in get_prep_value
    return int(value)
ValueError: invalid literal for int() with base 10: '2hbpw7ncf4'

The above exception was the direct cause of the following exception:

Traceback (most recent call last):
  File "D:\python38\lib\site-packages\django\core\handlers\exception.py", line 55, in inner
    response = get_response(request)
  File "D:\python38\lib\site-packages\django\core\handlers\base.py", line 197, in _get_response
    response = wrapped_callback(request, *callback_args, **callback_kwargs)
  File "D:\python38\lib\site-packages\django\views\decorators\csrf.py", line 56, in wrapper_view
    return view_func(*args, **kwargs)
  File "D:\JOB\freelance10\converter\users\decorators.py", line 46, in wrapper
    return func(request, *args, **kwargs)
  File "D:\JOB\freelance10\converter\payment\views.py", line 46, in catch_payment
    order.save()
  File "D:\JOB\freelance10\converter\convert_order\models.py", line 36, in save
    super(ConvertOrder, self).save(*args, **kwargs) ### ÏÅÐÅÃÐÓÆÀÅÒ ÑÈÑÒÅÌÓ !!!!
  File "D:\python38\lib\site-packages\django\db\models\base.py", line 814, in save
    self.save_base(
  File "D:\python38\lib\site-packages\django\db\models\base.py", line 877, in save_base
    updated = self._save_table(
  File "D:\python38\lib\site-packages\django\db\models\base.py", line 990, in _save_table
    updated = self._do_update(
  File "D:\python38\lib\site-packages\django\db\models\base.py", line 1054, in _do_update
    return filtered._update(values) > 0
  File "D:\python38\lib\site-packages\django\db\models\query.py", line 1231, in _update
    return query.get_compiler(self.db).execute_sql(CURSOR)
  File "D:\python38\lib\site-packages\django\db\models\sql\compiler.py", line 1984, in execute_sql
    cursor = super().execute_sql(result_type)
  File "D:\python38\lib\site-packages\django\db\models\sql\compiler.py", line 1549, in execute_sql
    sql, params = self.as_sql()
  File "D:\python38\lib\site-packages\django\db\models\sql\compiler.py", line 1947, in as_sql
    val = field.get_db_prep_save(val, connection=self.connection)
  File "D:\python38\lib\site-packages\django\db\models\fields\__init__.py", line 954, in get_db_prep_save
    return self.get_db_prep_value(value, connection=connection, prepared=False)
  File "D:\python38\lib\site-packages\django\db\models\fields\__init__.py", line 2060, in get_db_prep_value
    value = super().get_db_prep_value(value, connection, prepared)
  File "D:\python38\lib\site-packages\django\db\models\fields\__init__.py", line 947, in get_db_prep_value
    value = self.get_prep_value(value)
  File "D:\python38\lib\site-packages\django\db\models\fields\__init__.py", line 2055, in get_prep_value
    raise e.__class__(
ValueError: Field 'price' expected a number but got '2hbpw7ncf4'.
Internal Server Error: /ru/payment/catch-payment/
Traceback (most recent call last):
  File "D:\python38\lib\site-packages\django\db\models\fields\__init__.py", line 2053, in get_prep_value
    return int(value)
ValueError: invalid literal for int() with base 10: '2hbpw7ncf4'

The above exception was the direct cause of the following exception:

Traceback (most recent call last):
  File "D:\python38\lib\site-packages\django\core\handlers\exception.py", line 55, in inner
    response = get_response(request)
  File "D:\python38\lib\site-packages\django\core\handlers\base.py", line 197, in _get_response
    response = wrapped_callback(request, *callback_args, **callback_kwargs)
  File "D:\python38\lib\site-packages\django\views\decorators\csrf.py", line 56, in wrapper_view
    return view_func(*args, **kwargs)
  File "D:\JOB\freelance10\converter\users\decorators.py", line 46, in wrapper
    return func(request, *args, **kwargs)
  File "D:\JOB\freelance10\converter\payment\views.py", line 46, in catch_payment
    order.save()
  File "D:\JOB\freelance10\converter\convert_order\models.py", line 36, in save
    super(ConvertOrder, self).save(*args, **kwargs) ### ÏÅÐÅÃÐÓÆÀÅÒ ÑÈÑÒÅÌÓ !!!!
  File "D:\python38\lib\site-packages\django\db\models\base.py", line 814, in save
    self.save_base(
  File "D:\python38\lib\site-packages\django\db\models\base.py", line 877, in save_base
    updated = self._save_table(
  File "D:\python38\lib\site-packages\django\db\models\base.py", line 990, in _save_table
    updated = self._do_update(
  File "D:\python38\lib\site-packages\django\db\models\base.py", line 1054, in _do_update
    return filtered._update(values) > 0
  File "D:\python38\lib\site-packages\django\db\models\query.py", line 1231, in _update
    return query.get_compiler(self.db).execute_sql(CURSOR)
  File "D:\python38\lib\site-packages\django\db\models\sql\compiler.py", line 1984, in execute_sql
    cursor = super().execute_sql(result_type)
  File "D:\python38\lib\site-packages\django\db\models\sql\compiler.py", line 1549, in execute_sql
    sql, params = self.as_sql()
  File "D:\python38\lib\site-packages\django\db\models\sql\compiler.py", line 1947, in as_sql
    val = field.get_db_prep_save(val, connection=self.connection)
  File "D:\python38\lib\site-packages\django\db\models\fields\__init__.py", line 954, in get_db_prep_save
    return self.get_db_prep_value(value, connection=connection, prepared=False)
  File "D:\python38\lib\site-packages\django\db\models\fields\__init__.py", line 2060, in get_db_prep_value
    value = super().get_db_prep_value(value, connection, prepared)
  File "D:\python38\lib\site-packages\django\db\models\fields\__init__.py", line 947, in get_db_prep_value
    value = self.get_prep_value(value)
  File "D:\python38\lib\site-packages\django\db\models\fields\__init__.py", line 2055, in get_prep_value
    raise e.__class__(
ValueError: Field 'price' expected a number but got '2hbpw7ncf4'.
D:\JOB\freelance10\converter\payment\views.py changed, reloading.
Watching for file changes with StatReloader
Internal Server Error: /ru/payment/catch-payment/
Traceback (most recent call last):
  File "D:\python38\lib\site-packages\django\utils\datastructures.py", line 84, in __getitem__
    list_ = super().__getitem__(key)
KeyError: 'price'

During handling of the above exception, another exception occurred:

Traceback (most recent call last):
  File "D:\python38\lib\site-packages\django\core\handlers\exception.py", line 55, in inner
    response = get_response(request)
  File "D:\python38\lib\site-packages\django\core\handlers\base.py", line 197, in _get_response
    response = wrapped_callback(request, *callback_args, **callback_kwargs)
  File "D:\python38\lib\site-packages\django\views\decorators\csrf.py", line 56, in wrapper_view
    return view_func(*args, **kwargs)
  File "D:\JOB\freelance10\converter\users\decorators.py", line 46, in wrapper
    return func(request, *args, **kwargs)
  File "D:\JOB\freelance10\converter\payment\views.py", line 44, in catch_payment
    order.price = request.POST['price']
  File "D:\python38\lib\site-packages\django\utils\datastructures.py", line 86, in __getitem__
    raise MultiValueDictKeyError(key)
django.utils.datastructures.MultiValueDictKeyError: 'price'
D:\JOB\freelance10\converter\payment\views.py changed, reloading.
Watching for file changes with StatReloader
D:\JOB\freelance10\converter\users\views.py changed, reloading.
Watching for file changes with StatReloader
D:\JOB\freelance10\converter\payment\views.py changed, reloading.
Watching for file changes with StatReloader
D:\JOB\freelance10\converter\payment\views.py changed, reloading.
Watching for file changes with StatReloader
D:\JOB\freelance10\converter\payment\views.py changed, reloading.
Watching for file changes with StatReloader
D:\JOB\freelance10\converter\payment\views.py changed, reloading.
Watching for file changes with StatReloader
D:\JOB\freelance10\converter\payment\views.py changed, reloading.
Watching for file changes with StatReloader
D:\JOB\freelance10\converter\payment\views.py changed, reloading.
Watching for file changes with StatReloader
D:\JOB\freelance10\converter\payment\views.py changed, reloading.
Watching for file changes with StatReloader
D:\JOB\freelance10\converter\payment\views.py changed, reloading.
Watching for file changes with StatReloader
D:\JOB\freelance10\converter\payment\views.py changed, reloading.
Watching for file changes with StatReloader
D:\JOB\freelance10\converter\payment\views.py changed, reloading.
Watching for file changes with StatReloader
D:\JOB\freelance10\converter\payment\views.py changed, reloading.
Watching for file changes with StatReloader
D:\JOB\freelance10\converter\payment\views.py changed, reloading.
Watching for file changes with StatReloader
D:\JOB\freelance10\converter\payment\views.py changed, reloading.
Watching for file changes with StatReloader
D:\JOB\freelance10\converter\payment\views.py changed, reloading.
Watching for file changes with StatReloader
Internal Server Error: /ru/payment/catch-payment/
Traceback (most recent call last):
  File "D:\python38\lib\site-packages\django\core\handlers\exception.py", line 55, in inner
    response = get_response(request)
  File "D:\python38\lib\site-packages\django\core\handlers\base.py", line 197, in _get_response
    response = wrapped_callback(request, *callback_args, **callback_kwargs)
  File "D:\python38\lib\site-packages\django\views\decorators\csrf.py", line 56, in wrapper_view
    return view_func(*args, **kwargs)
  File "D:\JOB\freelance10\converter\users\decorators.py", line 46, in wrapper
    return func(request, *args, **kwargs)
  File "D:\JOB\freelance10\converter\payment\views.py", line 40, in catch_payment
    POST_DATA = json.loads(request.POST)
  File "D:\python38\lib\json\__init__.py", line 341, in loads
    raise TypeError(f'the JSON object must be str, bytes or bytearray, '
TypeError: the JSON object must be str, bytes or bytearray, not QueryDict
Internal Server Error: /ru/payment/catch-payment/
Traceback (most recent call last):
  File "D:\python38\lib\site-packages\django\core\handlers\exception.py", line 55, in inner
    response = get_response(request)
  File "D:\python38\lib\site-packages\django\core\handlers\base.py", line 197, in _get_response
    response = wrapped_callback(request, *callback_args, **callback_kwargs)
  File "D:\python38\lib\site-packages\django\views\decorators\csrf.py", line 56, in wrapper_view
    return view_func(*args, **kwargs)
  File "D:\JOB\freelance10\converter\users\decorators.py", line 46, in wrapper
    return func(request, *args, **kwargs)
  File "D:\JOB\freelance10\converter\payment\views.py", line 40, in catch_payment
    POST_DATA = json.loads(request.POST)
  File "D:\python38\lib\json\__init__.py", line 341, in loads
    raise TypeError(f'the JSON object must be str, bytes or bytearray, '
TypeError: the JSON object must be str, bytes or bytearray, not QueryDict
Internal Server Error: /ru/payment/catch-payment/
Traceback (most recent call last):
  File "D:\python38\lib\site-packages\django\core\handlers\exception.py", line 55, in inner
    response = get_response(request)
  File "D:\python38\lib\site-packages\django\core\handlers\base.py", line 197, in _get_response
    response = wrapped_callback(request, *callback_args, **callback_kwargs)
  File "D:\python38\lib\site-packages\django\views\decorators\csrf.py", line 56, in wrapper_view
    return view_func(*args, **kwargs)
  File "D:\JOB\freelance10\converter\users\decorators.py", line 46, in wrapper
    return func(request, *args, **kwargs)
  File "D:\JOB\freelance10\converter\payment\views.py", line 40, in catch_payment
    POST_DATA = json.loads(request.POST)
  File "D:\python38\lib\json\__init__.py", line 341, in loads
    raise TypeError(f'the JSON object must be str, bytes or bytearray, '
TypeError: the JSON object must be str, bytes or bytearray, not QueryDict
Internal Server Error: /ru/payment/catch-payment/
Traceback (most recent call last):
  File "D:\python38\lib\site-packages\django\core\handlers\exception.py", line 55, in inner
    response = get_response(request)
  File "D:\python38\lib\site-packages\django\core\handlers\base.py", line 197, in _get_response
    response = wrapped_callback(request, *callback_args, **callback_kwargs)
  File "D:\python38\lib\site-packages\django\views\decorators\csrf.py", line 56, in wrapper_view
    return view_func(*args, **kwargs)
  File "D:\JOB\freelance10\converter\users\decorators.py", line 46, in wrapper
    return func(request, *args, **kwargs)
  File "D:\JOB\freelance10\converter\payment\views.py", line 40, in catch_payment
    POST_DATA = json.loads(request.POST)
  File "D:\python38\lib\json\__init__.py", line 341, in loads
    raise TypeError(f'the JSON object must be str, bytes or bytearray, '
TypeError: the JSON object must be str, bytes or bytearray, not QueryDict
Internal Server Error: /ru/payment/catch-payment/
Traceback (most recent call last):
  File "D:\python38\lib\site-packages\django\core\handlers\exception.py", line 55, in inner
    response = get_response(request)
  File "D:\python38\lib\site-packages\django\core\handlers\base.py", line 197, in _get_response
    response = wrapped_callback(request, *callback_args, **callback_kwargs)
  File "D:\python38\lib\site-packages\django\views\decorators\csrf.py", line 56, in wrapper_view
    return view_func(*args, **kwargs)
  File "D:\JOB\freelance10\converter\users\decorators.py", line 46, in wrapper
    return func(request, *args, **kwargs)
  File "D:\JOB\freelance10\converter\payment\views.py", line 40, in catch_payment
    POST_DATA = json.loads(request.POST)
  File "D:\python38\lib\json\__init__.py", line 341, in loads
    raise TypeError(f'the JSON object must be str, bytes or bytearray, '
TypeError: the JSON object must be str, bytes or bytearray, not QueryDict
Internal Server Error: /ru/payment/catch-payment/
Traceback (most recent call last):
  File "D:\python38\lib\site-packages\django\core\handlers\exception.py", line 55, in inner
    response = get_response(request)
  File "D:\python38\lib\site-packages\django\core\handlers\base.py", line 197, in _get_response
    response = wrapped_callback(request, *callback_args, **callback_kwargs)
  File "D:\python38\lib\site-packages\django\views\decorators\csrf.py", line 56, in wrapper_view
    return view_func(*args, **kwargs)
  File "D:\JOB\freelance10\converter\users\decorators.py", line 46, in wrapper
    return func(request, *args, **kwargs)
  File "D:\JOB\freelance10\converter\payment\views.py", line 40, in catch_payment
    POST_DATA = json.loads(request.POST)
  File "D:\python38\lib\json\__init__.py", line 341, in loads
    raise TypeError(f'the JSON object must be str, bytes or bytearray, '
TypeError: the JSON object must be str, bytes or bytearray, not QueryDict
Internal Server Error: /ru/payment/catch-payment/
Traceback (most recent call last):
  File "D:\python38\lib\site-packages\django\core\handlers\exception.py", line 55, in inner
    response = get_response(request)
  File "D:\python38\lib\site-packages\django\core\handlers\base.py", line 197, in _get_response
    response = wrapped_callback(request, *callback_args, **callback_kwargs)
  File "D:\python38\lib\site-packages\django\views\decorators\csrf.py", line 56, in wrapper_view
    return view_func(*args, **kwargs)
  File "D:\JOB\freelance10\converter\users\decorators.py", line 46, in wrapper
    return func(request, *args, **kwargs)
  File "D:\JOB\freelance10\converter\payment\views.py", line 40, in catch_payment
    POST_DATA = json.loads(request.POST)
  File "D:\python38\lib\json\__init__.py", line 341, in loads
    raise TypeError(f'the JSON object must be str, bytes or bytearray, '
TypeError: the JSON object must be str, bytes or bytearray, not QueryDict
Internal Server Error: /ru/payment/catch-payment/
Traceback (most recent call last):
  File "D:\python38\lib\site-packages\django\core\handlers\exception.py", line 55, in inner
    response = get_response(request)
  File "D:\python38\lib\site-packages\django\core\handlers\base.py", line 197, in _get_response
    response = wrapped_callback(request, *callback_args, **callback_kwargs)
  File "D:\python38\lib\site-packages\django\views\decorators\csrf.py", line 56, in wrapper_view
    return view_func(*args, **kwargs)
  File "D:\JOB\freelance10\converter\users\decorators.py", line 46, in wrapper
    return func(request, *args, **kwargs)
  File "D:\JOB\freelance10\converter\payment\views.py", line 40, in catch_payment
    POST_DATA = json.loads(request.POST)
  File "D:\python38\lib\json\__init__.py", line 341, in loads
    raise TypeError(f'the JSON object must be str, bytes or bytearray, '
TypeError: the JSON object must be str, bytes or bytearray, not QueryDict
Internal Server Error: /ru/payment/catch-payment/
Traceback (most recent call last):
  File "D:\python38\lib\site-packages\django\core\handlers\exception.py", line 55, in inner
    response = get_response(request)
  File "D:\python38\lib\site-packages\django\core\handlers\base.py", line 197, in _get_response
    response = wrapped_callback(request, *callback_args, **callback_kwargs)
  File "D:\python38\lib\site-packages\django\views\decorators\csrf.py", line 56, in wrapper_view
    return view_func(*args, **kwargs)
  File "D:\JOB\freelance10\converter\users\decorators.py", line 46, in wrapper
    return func(request, *args, **kwargs)
  File "D:\JOB\freelance10\converter\payment\views.py", line 40, in catch_payment
    POST_DATA = json.loads(request.POST)
  File "D:\python38\lib\json\__init__.py", line 341, in loads
    raise TypeError(f'the JSON object must be str, bytes or bytearray, '
TypeError: the JSON object must be str, bytes or bytearray, not QueryDict
Internal Server Error: /ru/payment/catch-payment/
Traceback (most recent call last):
  File "D:\python38\lib\site-packages\django\core\handlers\exception.py", line 55, in inner
    response = get_response(request)
  File "D:\python38\lib\site-packages\django\core\handlers\base.py", line 197, in _get_response
    response = wrapped_callback(request, *callback_args, **callback_kwargs)
  File "D:\python38\lib\site-packages\django\views\decorators\csrf.py", line 56, in wrapper_view
    return view_func(*args, **kwargs)
  File "D:\JOB\freelance10\converter\users\decorators.py", line 46, in wrapper
    return func(request, *args, **kwargs)
  File "D:\JOB\freelance10\converter\payment\views.py", line 40, in catch_payment
    POST_DATA = json.loads(request.POST)
  File "D:\python38\lib\json\__init__.py", line 341, in loads
    raise TypeError(f'the JSON object must be str, bytes or bytearray, '
TypeError: the JSON object must be str, bytes or bytearray, not QueryDict
Watching for file changes with StatReloader
Internal Server Error: /ru/payment/catch-payment/
Traceback (most recent call last):
  File "D:\python38\lib\site-packages\django\core\handlers\exception.py", line 55, in inner
    response = get_response(request)
  File "D:\python38\lib\site-packages\django\core\handlers\base.py", line 197, in _get_response
    response = wrapped_callback(request, *callback_args, **callback_kwargs)
  File "D:\python38\lib\site-packages\django\views\decorators\csrf.py", line 56, in wrapper_view
    return view_func(*args, **kwargs)
  File "D:\JOB\freelance10\converter\users\decorators.py", line 46, in wrapper
    return func(request, *args, **kwargs)
  File "D:\JOB\freelance10\converter\payment\views.py", line 40, in catch_payment
    POST_DATA = json.loads(request.POST)
  File "D:\python38\lib\json\__init__.py", line 341, in loads
    raise TypeError(f'the JSON object must be str, bytes or bytearray, '
TypeError: the JSON object must be str, bytes or bytearray, not QueryDict
Internal Server Error: /ru/payment/catch-payment/
Traceback (most recent call last):
  File "D:\python38\lib\site-packages\django\core\handlers\exception.py", line 55, in inner
    response = get_response(request)
  File "D:\python38\lib\site-packages\django\core\handlers\base.py", line 197, in _get_response
    response = wrapped_callback(request, *callback_args, **callback_kwargs)
  File "D:\python38\lib\site-packages\django\views\decorators\csrf.py", line 56, in wrapper_view
    return view_func(*args, **kwargs)
  File "D:\JOB\freelance10\converter\users\decorators.py", line 46, in wrapper
    return func(request, *args, **kwargs)
  File "D:\JOB\freelance10\converter\payment\views.py", line 40, in catch_payment
    POST_DATA = json.loads(request.POST)
  File "D:\python38\lib\json\__init__.py", line 341, in loads
    raise TypeError(f'the JSON object must be str, bytes or bytearray, '
TypeError: the JSON object must be str, bytes or bytearray, not QueryDict
Internal Server Error: /ru/payment/catch-payment/
Traceback (most recent call last):
  File "D:\python38\lib\site-packages\django\core\handlers\exception.py", line 55, in inner
    response = get_response(request)
  File "D:\python38\lib\site-packages\django\core\handlers\base.py", line 197, in _get_response
    response = wrapped_callback(request, *callback_args, **callback_kwargs)
  File "D:\python38\lib\site-packages\django\views\decorators\csrf.py", line 56, in wrapper_view
    return view_func(*args, **kwargs)
  File "D:\JOB\freelance10\converter\users\decorators.py", line 46, in wrapper
    return func(request, *args, **kwargs)
  File "D:\JOB\freelance10\converter\payment\views.py", line 40, in catch_payment
    POST_DATA = json.loads(request.POST)
  File "D:\python38\lib\json\__init__.py", line 341, in loads
    raise TypeError(f'the JSON object must be str, bytes or bytearray, '
TypeError: the JSON object must be str, bytes or bytearray, not QueryDict
Internal Server Error: /ru/payment/catch-payment/
Traceback (most recent call last):
  File "D:\python38\lib\site-packages\django\core\handlers\exception.py", line 55, in inner
    response = get_response(request)
  File "D:\python38\lib\site-packages\django\core\handlers\base.py", line 197, in _get_response
    response = wrapped_callback(request, *callback_args, **callback_kwargs)
  File "D:\python38\lib\site-packages\django\views\decorators\csrf.py", line 56, in wrapper_view
    return view_func(*args, **kwargs)
  File "D:\JOB\freelance10\converter\users\decorators.py", line 46, in wrapper
    return func(request, *args, **kwargs)
  File "D:\JOB\freelance10\converter\payment\views.py", line 40, in catch_payment
    POST_DATA = json.loads(request.POST)
  File "D:\python38\lib\json\__init__.py", line 341, in loads
    raise TypeError(f'the JSON object must be str, bytes or bytearray, '
TypeError: the JSON object must be str, bytes or bytearray, not QueryDict
Internal Server Error: /ru/payment/catch-payment/
Traceback (most recent call last):
  File "D:\python38\lib\site-packages\django\core\handlers\exception.py", line 55, in inner
    response = get_response(request)
  File "D:\python38\lib\site-packages\django\core\handlers\base.py", line 197, in _get_response
    response = wrapped_callback(request, *callback_args, **callback_kwargs)
  File "D:\python38\lib\site-packages\django\views\decorators\csrf.py", line 56, in wrapper_view
    return view_func(*args, **kwargs)
  File "D:\JOB\freelance10\converter\users\decorators.py", line 46, in wrapper
    return func(request, *args, **kwargs)
  File "D:\JOB\freelance10\converter\payment\views.py", line 40, in catch_payment
    POST_DATA = json.loads(request.POST)
  File "D:\python38\lib\json\__init__.py", line 341, in loads
    raise TypeError(f'the JSON object must be str, bytes or bytearray, '
TypeError: the JSON object must be str, bytes or bytearray, not QueryDict
Internal Server Error: /ru/payment/catch-payment/
Traceback (most recent call last):
  File "D:\python38\lib\site-packages\django\core\handlers\exception.py", line 55, in inner
    response = get_response(request)
  File "D:\python38\lib\site-packages\django\core\handlers\base.py", line 197, in _get_response
    response = wrapped_callback(request, *callback_args, **callback_kwargs)
  File "D:\python38\lib\site-packages\django\views\decorators\csrf.py", line 56, in wrapper_view
    return view_func(*args, **kwargs)
  File "D:\JOB\freelance10\converter\users\decorators.py", line 46, in wrapper
    return func(request, *args, **kwargs)
  File "D:\JOB\freelance10\converter\payment\views.py", line 40, in catch_payment
    POST_DATA = json.loads(request.POST)
  File "D:\python38\lib\json\__init__.py", line 341, in loads
    raise TypeError(f'the JSON object must be str, bytes or bytearray, '
TypeError: the JSON object must be str, bytes or bytearray, not QueryDict
D:\JOB\freelance10\converter\payment\views.py changed, reloading.
Watching for file changes with StatReloader
Internal Server Error: /ru/payment/catch-payment/
Traceback (most recent call last):
  File "D:\python38\lib\site-packages\django\db\models\fields\__init__.py", line 2053, in get_prep_value
    return int(value)
ValueError: invalid literal for int() with base 10: '310.00'

The above exception was the direct cause of the following exception:

Traceback (most recent call last):
  File "D:\python38\lib\site-packages\django\core\handlers\exception.py", line 55, in inner
    response = get_response(request)
  File "D:\python38\lib\site-packages\django\core\handlers\base.py", line 197, in _get_response
    response = wrapped_callback(request, *callback_args, **callback_kwargs)
  File "D:\python38\lib\site-packages\django\views\decorators\csrf.py", line 56, in wrapper_view
    return view_func(*args, **kwargs)
  File "D:\JOB\freelance10\converter\users\decorators.py", line 46, in wrapper
    return func(request, *args, **kwargs)
  File "D:\JOB\freelance10\converter\payment\views.py", line 46, in catch_payment
    order.save()
  File "D:\JOB\freelance10\converter\convert_order\models.py", line 36, in save
    super(ConvertOrder, self).save(*args, **kwargs) ### ÏÅÐÅÃÐÓÆÀÅÒ ÑÈÑÒÅÌÓ !!!!
  File "D:\python38\lib\site-packages\django\db\models\base.py", line 814, in save
    self.save_base(
  File "D:\python38\lib\site-packages\django\db\models\base.py", line 877, in save_base
    updated = self._save_table(
  File "D:\python38\lib\site-packages\django\db\models\base.py", line 990, in _save_table
    updated = self._do_update(
  File "D:\python38\lib\site-packages\django\db\models\base.py", line 1054, in _do_update
    return filtered._update(values) > 0
  File "D:\python38\lib\site-packages\django\db\models\query.py", line 1231, in _update
    return query.get_compiler(self.db).execute_sql(CURSOR)
  File "D:\python38\lib\site-packages\django\db\models\sql\compiler.py", line 1984, in execute_sql
    cursor = super().execute_sql(result_type)
  File "D:\python38\lib\site-packages\django\db\models\sql\compiler.py", line 1549, in execute_sql
    sql, params = self.as_sql()
  File "D:\python38\lib\site-packages\django\db\models\sql\compiler.py", line 1947, in as_sql
    val = field.get_db_prep_save(val, connection=self.connection)
  File "D:\python38\lib\site-packages\django\db\models\fields\__init__.py", line 954, in get_db_prep_save
    return self.get_db_prep_value(value, connection=connection, prepared=False)
  File "D:\python38\lib\site-packages\django\db\models\fields\__init__.py", line 2060, in get_db_prep_value
    value = super().get_db_prep_value(value, connection, prepared)
  File "D:\python38\lib\site-packages\django\db\models\fields\__init__.py", line 947, in get_db_prep_value
    value = self.get_prep_value(value)
  File "D:\python38\lib\site-packages\django\db\models\fields\__init__.py", line 2055, in get_prep_value
    raise e.__class__(
ValueError: Field 'price' expected a number but got '310.00'.
Internal Server Error: /ru/payment/catch-payment/
Traceback (most recent call last):
  File "D:\python38\lib\site-packages\django\db\models\fields\__init__.py", line 2053, in get_prep_value
    return int(value)
ValueError: invalid literal for int() with base 10: '310.00'

The above exception was the direct cause of the following exception:

Traceback (most recent call last):
  File "D:\python38\lib\site-packages\django\core\handlers\exception.py", line 55, in inner
    response = get_response(request)
  File "D:\python38\lib\site-packages\django\core\handlers\base.py", line 197, in _get_response
    response = wrapped_callback(request, *callback_args, **callback_kwargs)
  File "D:\python38\lib\site-packages\django\views\decorators\csrf.py", line 56, in wrapper_view
    return view_func(*args, **kwargs)
  File "D:\JOB\freelance10\converter\users\decorators.py", line 46, in wrapper
    return func(request, *args, **kwargs)
  File "D:\JOB\freelance10\converter\payment\views.py", line 46, in catch_payment
    order.save()
  File "D:\JOB\freelance10\converter\convert_order\models.py", line 36, in save
    super(ConvertOrder, self).save(*args, **kwargs) ### ÏÅÐÅÃÐÓÆÀÅÒ ÑÈÑÒÅÌÓ !!!!
  File "D:\python38\lib\site-packages\django\db\models\base.py", line 814, in save
    self.save_base(
  File "D:\python38\lib\site-packages\django\db\models\base.py", line 877, in save_base
    updated = self._save_table(
  File "D:\python38\lib\site-packages\django\db\models\base.py", line 990, in _save_table
    updated = self._do_update(
  File "D:\python38\lib\site-packages\django\db\models\base.py", line 1054, in _do_update
    return filtered._update(values) > 0
  File "D:\python38\lib\site-packages\django\db\models\query.py", line 1231, in _update
    return query.get_compiler(self.db).execute_sql(CURSOR)
  File "D:\python38\lib\site-packages\django\db\models\sql\compiler.py", line 1984, in execute_sql
    cursor = super().execute_sql(result_type)
  File "D:\python38\lib\site-packages\django\db\models\sql\compiler.py", line 1549, in execute_sql
    sql, params = self.as_sql()
  File "D:\python38\lib\site-packages\django\db\models\sql\compiler.py", line 1947, in as_sql
    val = field.get_db_prep_save(val, connection=self.connection)
  File "D:\python38\lib\site-packages\django\db\models\fields\__init__.py", line 954, in get_db_prep_save
    return self.get_db_prep_value(value, connection=connection, prepared=False)
  File "D:\python38\lib\site-packages\django\db\models\fields\__init__.py", line 2060, in get_db_prep_value
    value = super().get_db_prep_value(value, connection, prepared)
  File "D:\python38\lib\site-packages\django\db\models\fields\__init__.py", line 947, in get_db_prep_value
    value = self.get_prep_value(value)
  File "D:\python38\lib\site-packages\django\db\models\fields\__init__.py", line 2055, in get_prep_value
    raise e.__class__(
ValueError: Field 'price' expected a number but got '310.00'.
D:\JOB\freelance10\converter\payment\views.py changed, reloading.
Watching for file changes with StatReloader
Watching for file changes with StatReloader
Internal Server Error: /ru/payment/catch-payment/
Traceback (most recent call last):
  File "D:\python38\lib\site-packages\django\core\handlers\exception.py", line 55, in inner
    response = get_response(request)
  File "D:\python38\lib\site-packages\django\core\handlers\base.py", line 197, in _get_response
    response = wrapped_callback(request, *callback_args, **callback_kwargs)
  File "D:\python38\lib\site-packages\django\views\decorators\csrf.py", line 56, in wrapper_view
    return view_func(*args, **kwargs)
  File "D:\JOB\freelance10\converter\users\decorators.py", line 46, in wrapper
    return func(request, *args, **kwargs)
  File "D:\JOB\freelance10\converter\payment\views.py", line 44, in catch_payment
    order.price = int(request.POST['original_amount'])
ValueError: invalid literal for int() with base 10: '310.00'
D:\JOB\freelance10\converter\payment\views.py changed, reloading.
Watching for file changes with StatReloader
Not Found: /ad
D:\JOB\freelance10\converter\convert_order\admin.py changed, reloading.
Watching for file changes with StatReloader
D:\JOB\freelance10\converter\convert_order\admin.py changed, reloading.
Watching for file changes with StatReloader
D:\JOB\freelance10\converter\convert_order\admin.py changed, reloading.
Watching for file changes with StatReloader
D:\JOB\freelance10\converter\convert_order\models.py changed, reloading.
Watching for file changes with StatReloader
D:\JOB\freelance10\converter\convert_order\models.py changed, reloading.
Watching for file changes with StatReloader
D:\JOB\freelance10\converter\convert_order\models.py changed, reloading.
Watching for file changes with StatReloader
D:\JOB\freelance10\converter\convert_order\models.py changed, reloading.
Watching for file changes with StatReloader
D:\JOB\freelance10\converter\users\views.py changed, reloading.
Watching for file changes with StatReloader
D:\JOB\freelance10\converter\users\views.py changed, reloading.
Watching for file changes with StatReloader
D:\JOB\freelance10\converter\users\views.py changed, reloading.
Watching for file changes with StatReloader
D:\JOB\freelance10\converter\users\views.py changed, reloading.
Watching for file changes with StatReloader
D:\JOB\freelance10\converter\users\views.py changed, reloading.
Watching for file changes with StatReloader
D:\JOB\freelance10\converter\users\views.py changed, reloading.
Watching for file changes with StatReloader
D:\JOB\freelance10\converter\convert_order\views.py changed, reloading.
Watching for file changes with StatReloader
Watching for file changes with StatReloader
